<?xml version="1.0" ?>
<!-- =================================================================================== -->
<!-- |    This document was autogenerated by xacro from /home/nils/Documents/Studium/Studienarbeit/DossArm/src/dossarm_description/urdf/dossarm.urdf.xacro | -->
<!-- |    EDITING THIS FILE BY HAND IS NOT RECOMMENDED                                 | -->
<!-- =================================================================================== -->
<robot name="moveo_description">
    <!-- https://bitbucket.org/theconstructcore/my-robotic-manipulator/src/master/urdf/links_joints.xacro -->
    <link name="world" />
    <!-- <xacro:include filename="$(find dossarm_description)/urdf/links_joints.xacro" /> -->
    <link name="base">
        
<inertial>
            <mass value="0.1" />
            <origin rpy="1.5707 0 0" xyz="0  0 0" />
            <inertia ixx="0.03" ixy="0.0" ixz="0.0" iyy="0.03" iyz="0.0" izz="0.03" />
        </inertial>

        <collision>
            <origin rpy="1.5707 0 0" xyz="0  0 0" />
            <geometry>
                <mesh filename="package://dossarm_description/meshes/Motor_1_Case.stl" scale="0.00 0.001 0.001" />
            </geometry>
        </collision>
        <visual>
            <origin rpy="1.5707 0 0" xyz="0  0 0" />
            <geometry>
                <mesh filename="package://dossarm_description/meshes/Motor_1_Case.stl" scale="0.001 0.001 0.001" />
            </geometry>
            <material name="">
                <color rgba="0.79216 0.81961 0.93333 1" />
            </material>
        </visual>
    </link>
    <joint name="world_to_base=" type="fixed">
        <parent link="world" />
        <child link="base" />
        <origin rpy="0 0 0" xyz="0  0 -1" />
    </joint>
    <link name="Motor_1">
        
<inertial>
            <mass value="0.1" />
            <origin rpy="1.5708 0 0" xyz="0 0 0" />
            <inertia ixx="0.03" ixy="0.0" ixz="0.0" iyy="0.03" iyz="0.0" izz="0.03" />
        </inertial>

        <collision>
            <origin rpy="1.5708 0 0" xyz="0 0 0" />
            <geometry>
                <mesh filename="package://dossarm_description/meshes/PH54_200.stl" scale="0.00 0.001 0.001" />
            </geometry>
        </collision>
        <visual>
            <origin rpy="1.5708 0 0" xyz="0 0 0" />
            <geometry>
                <mesh filename="package://dossarm_description/meshes/PH54_200.stl" scale="0.001 0.001 0.001" />
            </geometry>
            <material name="">
                <color rgba="0.79216 0.81961 0.93333 1" />
            </material>
        </visual>
    </link>
    <joint name="joint_base-motor_1" type="fixed">
        <axis xyz="0 0 0" />
        <limit effort="5" lower="-1.5707" upper="1.5707" velocity="1" />
        <origin rpy="0 0 0" xyz="0 0 0.064" />
        <parent link="base" />
        <child link="Motor_1" />
    </joint>
    <transmission name="trans_joint_base-motor_1">
        <type>hardware_interface/PositionJointInterface</type>
        <joint name="joint_base-motor_1">
            <hardwareInterface>hardware_interface/PositionJointInterface</hardwareInterface>
        </joint>
        <actuator name="motor_joint_base-motor_1">
            <hardwareInterface>hardware_interface/PositionJointInterface</hardwareInterface>
            <mechanicalReduction>1</mechanicalReduction>
        </actuator>
    </transmission>
    <link name="Link_1">
        
<inertial>
            <mass value="0.1" />
            <origin rpy="1.5708 0 0" xyz="0 0  0" />
            <inertia ixx="0.03" ixy="0.0" ixz="0.0" iyy="0.03" iyz="0.0" izz="0.03" />
        </inertial>

        <collision>
            <origin rpy="1.5708 0 0" xyz="0 0  0" />
            <geometry>
                <mesh filename="package://dossarm_description/meshes/Motor_2_Case.stl" scale="0.00 0.001 0.001" />
            </geometry>
        </collision>
        <visual>
            <origin rpy="1.5708 0 0" xyz="0 0  0" />
            <geometry>
                <mesh filename="package://dossarm_description/meshes/Motor_2_Case.stl" scale="0.001 0.001 0.001" />
            </geometry>
            <material name="">
                <color rgba="0.79216 0.81961 0.93333 1" />
            </material>
        </visual>
    </link>
    <joint name="Joint_1" type="continuous">
        <axis xyz="0 0 1" />
        <limit effort="5" lower="-1.5707" upper="1.5707" velocity="1" />
        <origin rpy="0 0 0" xyz="0 0 0.095" />
        <parent link="Motor_1" />
        <child link="Link_1" />
    </joint>
    <transmission name="trans_Joint_1">
        <type>hardware_interface/PositionJointInterface</type>
        <joint name="Joint_1">
            <hardwareInterface>hardware_interface/PositionJointInterface</hardwareInterface>
        </joint>
        <actuator name="motor_Joint_1">
            <hardwareInterface>hardware_interface/PositionJointInterface</hardwareInterface>
            <mechanicalReduction>1</mechanicalReduction>
        </actuator>
    </transmission>
    <link name="Motor_2">
        
<inertial>
            <mass value="0.1" />
            <origin rpy="0 0 0" xyz=" 0 0 0" />
            <inertia ixx="0.03" ixy="0.0" ixz="0.0" iyy="0.03" iyz="0.0" izz="0.03" />
        </inertial>

        <collision>
            <origin rpy="0 0 0" xyz=" 0 0 0" />
            <geometry>
                <mesh filename="package://dossarm_description/meshes/PH54_200_Bearings.stl" scale="0.00 0.001 0.001" />
            </geometry>
        </collision>
        <visual>
            <origin rpy="0 0 0" xyz=" 0 0 0" />
            <geometry>
                <mesh filename="package://dossarm_description/meshes/PH54_200_Bearings.stl" scale="0.001 0.001 0.001" />
            </geometry>
            <material name="">
                <color rgba="0.79216 0.81961 0.93333 1" />
            </material>
        </visual>
    </link>
    <joint name="joint_Link_2-motor_1" type="fixed">
        <axis xyz="0 0 0" />
        <limit effort="5" lower="-1.5707" upper="1.5707" velocity="1" />
        <origin rpy="0 0 1.5708" xyz="-0.00575 0 0  " />
        <parent link="Link_1" />
        <child link="Motor_2" />
    </joint>
    <transmission name="trans_joint_Link_2-motor_1">
        <type>hardware_interface/PositionJointInterface</type>
        <joint name="joint_Link_2-motor_1">
            <hardwareInterface>hardware_interface/PositionJointInterface</hardwareInterface>
        </joint>
        <actuator name="motor_joint_Link_2-motor_1">
            <hardwareInterface>hardware_interface/PositionJointInterface</hardwareInterface>
            <mechanicalReduction>1</mechanicalReduction>
        </actuator>
    </transmission>
    <link name="shoulder">
        
<inertial>
            <mass value="0.1" />
            <origin rpy="0 0 0" xyz="0 0 0" />
            <inertia ixx="0.03" ixy="0.0" ixz="0.0" iyy="0.03" iyz="0.0" izz="0.03" />
        </inertial>

        <collision>
            <origin rpy="0 0 0" xyz="0 0 0" />
            <geometry>
                <mesh filename="package://dossarm_description/meshes/Shoulder_complete.stl" scale="0.00 0.001 0.001" />
            </geometry>
        </collision>
        <visual>
            <origin rpy="0 0 0" xyz="0 0 0" />
            <geometry>
                <mesh filename="package://dossarm_description/meshes/Shoulder_complete.stl" scale="0.001 0.001 0.001" />
            </geometry>
            <material name="">
                <color rgba="0.79216 0.81961 0.93333 1" />
            </material>
        </visual>
    </link>
    <joint name="Joint_2" type="revolute">
        <axis xyz="1 0 0" />
        <limit effort="5" lower="-1.5707" upper="1.5707" velocity="1" />
        <origin rpy="0 0 1.5708" xyz="0 -0.00575 0" />
        <parent link="Motor_2" />
        <child link="shoulder" />
    </joint>
    <transmission name="trans_Joint_2">
        <type>hardware_interface/PositionJointInterface</type>
        <joint name="Joint_2">
            <hardwareInterface>hardware_interface/PositionJointInterface</hardwareInterface>
        </joint>
        <actuator name="motor_Joint_2">
            <hardwareInterface>hardware_interface/PositionJointInterface</hardwareInterface>
            <mechanicalReduction>1</mechanicalReduction>
        </actuator>
    </transmission>
    <link name="Motor_3">
        
<inertial>
            <mass value="0.1" />
            <origin rpy="0 0 0 " xyz=" 0 0 0" />
            <inertia ixx="0.03" ixy="0.0" ixz="0.0" iyy="0.03" iyz="0.0" izz="0.03" />
        </inertial>

        <collision>
            <origin rpy="0 0 0 " xyz=" 0 0 0" />
            <geometry>
                <mesh filename="package://dossarm_description/meshes/PH54_200_Bearings.stl" scale="0.00 0.001 0.001" />
            </geometry>
        </collision>
        <visual>
            <origin rpy="0 0 0 " xyz=" 0 0 0" />
            <geometry>
                <mesh filename="package://dossarm_description/meshes/PH54_200_Bearings.stl" scale="0.001 0.001 0.001" />
            </geometry>
            <material name="">
                <color rgba="0.79216 0.81961 0.93333 1" />
            </material>
        </visual>
    </link>
    <joint name="UpperArm_Motor_3_Connection" type="fixed">
        <axis xyz="0 0 0" />
        <limit effort="5" lower="-1.5707" upper="1.5707" velocity="1" />
        <origin rpy="0 0  0" xyz="0 0.00575 0.1" />
        <parent link="shoulder" />
        <child link="Motor_3" />
    </joint>
    <transmission name="trans_UpperArm_Motor_3_Connection">
        <type>hardware_interface/PositionJointInterface</type>
        <joint name="UpperArm_Motor_3_Connection">
            <hardwareInterface>hardware_interface/PositionJointInterface</hardwareInterface>
        </joint>
        <actuator name="motor_UpperArm_Motor_3_Connection">
            <hardwareInterface>hardware_interface/PositionJointInterface</hardwareInterface>
            <mechanicalReduction>1</mechanicalReduction>
        </actuator>
    </transmission>
    <link name="upperarm">
        
<inertial>
            <mass value="0.1" />
            <origin rpy="0 0 0 " xyz="0 0 0" />
            <inertia ixx="0.03" ixy="0.0" ixz="0.0" iyy="0.03" iyz="0.0" izz="0.03" />
        </inertial>

        <collision>
            <origin rpy="0 0 0 " xyz="0 0 0" />
            <geometry>
                <mesh filename="package://dossarm_description/meshes/upperarm_complete.stl" scale="0.00 0.001 0.001" />
            </geometry>
        </collision>
        <visual>
            <origin rpy="0 0 0 " xyz="0 0 0" />
            <geometry>
                <mesh filename="package://dossarm_description/meshes/upperarm_complete.stl" scale="0.001 0.001 0.001" />
            </geometry>
            <material name="">
                <color rgba="0.79216 0.81961 0.93333 1" />
            </material>
        </visual>
    </link>
    <joint name="Joint_3" type="revolute">
        <axis xyz="1 0 0" />
        <limit effort="5" lower="-1.5707" upper="1.5707" velocity="1" />
        <origin rpy="0 0 1.5708" xyz="0 -0.00575 0" />
        <parent link="Motor_3" />
        <child link="upperarm" />
    </joint>
    <transmission name="trans_Joint_3">
        <type>hardware_interface/PositionJointInterface</type>
        <joint name="Joint_3">
            <hardwareInterface>hardware_interface/PositionJointInterface</hardwareInterface>
        </joint>
        <actuator name="motor_Joint_3">
            <hardwareInterface>hardware_interface/PositionJointInterface</hardwareInterface>
            <mechanicalReduction>1</mechanicalReduction>
        </actuator>
    </transmission>
    <link name="Motor_4">
        
<inertial>
            <mass value="0.1" />
            <origin rpy="0 0 0" xyz="0 0 0" />
            <inertia ixx="0.03" ixy="0.0" ixz="0.0" iyy="0.03" iyz="0.0" izz="0.03" />
        </inertial>

        <collision>
            <origin rpy="0 0 0" xyz="0 0 0" />
            <geometry>
                <mesh filename="package://dossarm_description/meshes/PH54_200_Bearings.stl" scale="0.00 0.001 0.001" />
            </geometry>
        </collision>
        <visual>
            <origin rpy="0 0 0" xyz="0 0 0" />
            <geometry>
                <mesh filename="package://dossarm_description/meshes/PH54_200_Bearings.stl" scale="0.001 0.001 0.001" />
            </geometry>
            <material name="">
                <color rgba="0.79216 0.81961 0.93333 1" />
            </material>
        </visual>
    </link>
    <joint name="motor4_forearm_connection" type="fixed">
        <axis xyz="0 0 0" />
        <limit effort="5" lower="-1.5707" upper="1.5707" velocity="1" />
        <origin rpy="0 0 1.5708" xyz=" -0.00575 0 0.343041 " />
        <parent link="upperarm" />
        <child link="Motor_4" />
    </joint>
    <transmission name="trans_motor4_forearm_connection">
        <type>hardware_interface/PositionJointInterface</type>
        <joint name="motor4_forearm_connection">
            <hardwareInterface>hardware_interface/PositionJointInterface</hardwareInterface>
        </joint>
        <actuator name="motor_motor4_forearm_connection">
            <hardwareInterface>hardware_interface/PositionJointInterface</hardwareInterface>
            <mechanicalReduction>1</mechanicalReduction>
        </actuator>
    </transmission>
    <link name="forearm_upper">
        
<inertial>
            <mass value="0.1" />
            <origin rpy="0 0 0" xyz="0 0 0" />
            <inertia ixx="0.03" ixy="0.0" ixz="0.0" iyy="0.03" iyz="0.0" izz="0.03" />
        </inertial>

        <collision>
            <origin rpy="0 0 0" xyz="0 0 0" />
            <geometry>
                <mesh filename="package://dossarm_description/meshes/forearm_upper_complete.stl" scale="0.00 0.001 0.001" />
            </geometry>
        </collision>
        <visual>
            <origin rpy="0 0 0" xyz="0 0 0" />
            <geometry>
                <mesh filename="package://dossarm_description/meshes/forearm_upper_complete.stl" scale="0.001 0.001 0.001" />
            </geometry>
            <material name="">
                <color rgba="0.79216 0.81961 0.93333 1" />
            </material>
        </visual>
    </link>
    <joint name="Joint_4" type="revolute">
        <axis xyz="1 0 0" />
        <limit effort="5" lower="-1.5707" upper="1.5707" velocity="1" />
        <origin rpy="0 0  1.5708 " xyz=" 0   -0.00575  0" />
        <parent link="Motor_4" />
        <child link="forearm_upper" />
    </joint>
    <transmission name="trans_Joint_4">
        <type>hardware_interface/PositionJointInterface</type>
        <joint name="Joint_4">
            <hardwareInterface>hardware_interface/PositionJointInterface</hardwareInterface>
        </joint>
        <actuator name="motor_Joint_4">
            <hardwareInterface>hardware_interface/PositionJointInterface</hardwareInterface>
            <mechanicalReduction>1</mechanicalReduction>
        </actuator>
    </transmission>
    <link name="Motor_5">
        
<inertial>
            <mass value="0.1" />
            <origin rpy="0 0 0" xyz="0 0 0" />
            <inertia ixx="0.03" ixy="0.0" ixz="0.0" iyy="0.03" iyz="0.0" izz="0.03" />
        </inertial>

        <collision>
            <origin rpy="0 0 0" xyz="0 0 0" />
            <geometry>
                <mesh filename="package://dossarm_description/meshes/H54P-100_M54P-040.stl" scale="0.00 0.001 0.001" />
            </geometry>
        </collision>
        <visual>
            <origin rpy="0 0 0" xyz="0 0 0" />
            <geometry>
                <mesh filename="package://dossarm_description/meshes/H54P-100_M54P-040.stl" scale="0.001 0.001 0.001" />
            </geometry>
            <material name="">
                <color rgba="0.79216 0.81961 0.93333 1" />
            </material>
        </visual>
    </link>
    <joint name="forearm_lower_Motor5_connection" type="fixed">
        <axis xyz="0 0 0" />
        <limit effort="5" lower="-1.5707" upper="1.5707" velocity="1" />
        <origin rpy="1.5708 0 0" xyz=" 0 0 0.1775  " />
        <parent link="forearm_upper" />
        <child link="Motor_5" />
    </joint>
    <transmission name="trans_forearm_lower_Motor5_connection">
        <type>hardware_interface/PositionJointInterface</type>
        <joint name="forearm_lower_Motor5_connection">
            <hardwareInterface>hardware_interface/PositionJointInterface</hardwareInterface>
        </joint>
        <actuator name="motor_forearm_lower_Motor5_connection">
            <hardwareInterface>hardware_interface/PositionJointInterface</hardwareInterface>
            <mechanicalReduction>1</mechanicalReduction>
        </actuator>
    </transmission>
    <link name="forearm_lower">
        
<inertial>
            <mass value="0.1" />
            <origin rpy="0 0 0" xyz="0 0 0.124233" />
            <inertia ixx="0.03" ixy="0.0" ixz="0.0" iyy="0.03" iyz="0.0" izz="0.03" />
        </inertial>

        <collision>
            <origin rpy="0 0 0" xyz="0 0 0.124233" />
            <geometry>
                <mesh filename="package://dossarm_description/meshes/forearm_lower_complete.stl" scale="0.00 0.001 0.001" />
            </geometry>
        </collision>
        <visual>
            <origin rpy="0 0 0" xyz="0 0 0.124233" />
            <geometry>
                <mesh filename="package://dossarm_description/meshes/forearm_lower_complete.stl" scale="0.001 0.001 0.001" />
            </geometry>
            <material name="">
                <color rgba="0.79216 0.81961 0.93333 1" />
            </material>
        </visual>
    </link>
    <joint name="Joint_5" type="revolute">
        <axis xyz=" 0  0 1" />
        <limit effort="5" lower="-1.5707" upper="1.5707" velocity="1" />
        <origin rpy="-1.5708 0 0   " xyz=" 0 0 0 " />
        <parent link="Motor_5" />
        <child link="forearm_lower" />
    </joint>
    <transmission name="trans_Joint_5">
        <type>hardware_interface/PositionJointInterface</type>
        <joint name="Joint_5">
            <hardwareInterface>hardware_interface/PositionJointInterface</hardwareInterface>
        </joint>
        <actuator name="motor_Joint_5">
            <hardwareInterface>hardware_interface/PositionJointInterface</hardwareInterface>
            <mechanicalReduction>1</mechanicalReduction>
        </actuator>
    </transmission>
    <link name="Motor_6">
        
<inertial>
            <mass value="0.1" />
            <origin rpy="0 0 0" xyz="0 0 0" />
            <inertia ixx="0.03" ixy="0.0" ixz="0.0" iyy="0.03" iyz="0.0" izz="0.03" />
        </inertial>

        <collision>
            <origin rpy="0 0 0" xyz="0 0 0" />
            <geometry>
                <mesh filename="package://dossarm_description/meshes/PH42-020_Bearings.stl" scale="0.00 0.001 0.001" />
            </geometry>
        </collision>
        <visual>
            <origin rpy="0 0 0" xyz="0 0 0" />
            <geometry>
                <mesh filename="package://dossarm_description/meshes/PH42-020_Bearings.stl" scale="0.001 0.001 0.001" />
            </geometry>
            <material name="">
                <color rgba="0.79216 0.81961 0.93333 1" />
            </material>
        </visual>
    </link>
    <joint name="wrist_motor6_connection" type="fixed">
        <axis xyz="0 0 0" />
        <limit effort="5" lower="-1.5707" upper="1.5707" velocity="1" />
        <origin rpy="0 1.5708 0" xyz="0.039 0 0.124233" />
        <parent link="forearm_lower" />
        <child link="Motor_6" />
    </joint>
    <transmission name="trans_wrist_motor6_connection">
        <type>hardware_interface/PositionJointInterface</type>
        <joint name="wrist_motor6_connection">
            <hardwareInterface>hardware_interface/PositionJointInterface</hardwareInterface>
        </joint>
        <actuator name="motor_wrist_motor6_connection">
            <hardwareInterface>hardware_interface/PositionJointInterface</hardwareInterface>
            <mechanicalReduction>1</mechanicalReduction>
        </actuator>
    </transmission>
    <link name="wrist">
        
<inertial>
            <mass value="0.1" />
            <origin rpy="0 0 0" xyz="0 0 0" />
            <inertia ixx="0.03" ixy="0.0" ixz="0.0" iyy="0.03" iyz="0.0" izz="0.03" />
        </inertial>

        <collision>
            <origin rpy="0 0 0" xyz="0 0 0" />
            <geometry>
                <mesh filename="package://dossarm_description/meshes/wrist_complete.stl" scale="0.00 0.001 0.001" />
            </geometry>
        </collision>
        <visual>
            <origin rpy="0 0 0" xyz="0 0 0" />
            <geometry>
                <mesh filename="package://dossarm_description/meshes/wrist_complete.stl" scale="0.001 0.001 0.001" />
            </geometry>
            <material name="">
                <color rgba="0.79216 0.81961 0.93333 1" />
            </material>
        </visual>
    </link>
    <joint name="Joint_6" type="revolute">
        <axis xyz="0 1 0" />
        <limit effort="5" lower="-1.5707" upper="1.5707" velocity="1" />
        <origin rpy=" 1.5708 0 -1.5708 " xyz="  0 0 -0.039 " />
        <parent link="Motor_6" />
        <child link="wrist" />
    </joint>
    <transmission name="trans_Joint_6">
        <type>hardware_interface/PositionJointInterface</type>
        <joint name="Joint_6">
            <hardwareInterface>hardware_interface/PositionJointInterface</hardwareInterface>
        </joint>
        <actuator name="motor_Joint_6">
            <hardwareInterface>hardware_interface/PositionJointInterface</hardwareInterface>
            <mechanicalReduction>1</mechanicalReduction>
        </actuator>
    </transmission>
    <link name="Motor_7">
        
<inertial>
            <mass value="0.1" />
            <origin rpy="0 0 0" xyz="0 0 0" />
            <inertia ixx="0.03" ixy="0.0" ixz="0.0" iyy="0.03" iyz="0.0" izz="0.03" />
        </inertial>

        <collision>
            <origin rpy="0 0 0" xyz="0 0 0" />
            <geometry>
                <mesh filename="package://dossarm_description/meshes/PH42-020_Bearings.stl" scale="0.00 0.001 0.001" />
            </geometry>
        </collision>
        <visual>
            <origin rpy="0 0 0" xyz="0 0 0" />
            <geometry>
                <mesh filename="package://dossarm_description/meshes/PH42-020_Bearings.stl" scale="0.001 0.001 0.001" />
            </geometry>
            <material name="">
                <color rgba="0.79216 0.81961 0.93333 1" />
            </material>
        </visual>
    </link>
    <joint name="Motor_7_wrist_connection" type="fixed">
        <axis xyz="0 1 0" />
        <limit effort="5" lower="-1.5707" upper="1.5707" velocity="1" />
        <origin rpy=" 1.5708 0 1.5708" xyz="  0.039 0 0.082 " />
        <parent link="wrist" />
        <child link="Motor_7" />
    </joint>
    <transmission name="trans_Motor_7_wrist_connection">
        <type>hardware_interface/PositionJointInterface</type>
        <joint name="Motor_7_wrist_connection">
            <hardwareInterface>hardware_interface/PositionJointInterface</hardwareInterface>
        </joint>
        <actuator name="motor_Motor_7_wrist_connection">
            <hardwareInterface>hardware_interface/PositionJointInterface</hardwareInterface>
            <mechanicalReduction>1</mechanicalReduction>
        </actuator>
    </transmission>
    <link name="arm_ph42">
        
<inertial>
            <mass value="0.1" />
            <origin rpy="0 0 0" xyz="0 0 0" />
            <inertia ixx="0.03" ixy="0.0" ixz="0.0" iyy="0.03" iyz="0.0" izz="0.03" />
        </inertial>

        <collision>
            <origin rpy="0 0 0" xyz="0 0 0" />
            <geometry>
                <mesh filename="package://dossarm_description/meshes/Arm_PH42.stl" scale="0.00 0.001 0.001" />
            </geometry>
        </collision>
        <visual>
            <origin rpy="0 0 0" xyz="0 0 0" />
            <geometry>
                <mesh filename="package://dossarm_description/meshes/Arm_PH42.stl" scale="0.001 0.001 0.001" />
            </geometry>
            <material name="">
                <color rgba="0.79216 0.81961 0.93333 1" />
            </material>
        </visual>
    </link>
    <joint name="Joint_7" type="revolute">
        <axis xyz="1 0 0" />
        <limit effort="5" lower="-1.5707" upper="1.5707" velocity="1" />
        <origin rpy="  0 1.5708 0" xyz="  0 0 -0.039" />
        <parent link="Motor_7" />
        <child link="arm_ph42" />
    </joint>
    <transmission name="trans_Joint_7">
        <type>hardware_interface/PositionJointInterface</type>
        <joint name="Joint_7">
            <hardwareInterface>hardware_interface/PositionJointInterface</hardwareInterface>
        </joint>
        <actuator name="motor_Joint_7">
            <hardwareInterface>hardware_interface/PositionJointInterface</hardwareInterface>
            <mechanicalReduction>1</mechanicalReduction>
        </actuator>
    </transmission>
    <transmission name="trans_Joint_1">
        <type>transmission_interface/SimpleTransmission</type>
        <joint name="Joint_1">
            <hardwareInterface>hardware_interface/EffortJointInterface</hardwareInterface>
        </joint>
        <actuator name="Joint_1_motor">
            <hardwareInterface>hardware_interface/EffortJointInterface</hardwareInterface>
            <mechanicalReduction>1</mechanicalReduction>
        </actuator>
    </transmission>
    <transmission name="trans_Joint_2">
        <type>transmission_interface/SimpleTransmission</type>
        <joint name="Joint_2">
            <hardwareInterface>hardware_interface/EffortJointInterface</hardwareInterface>
        </joint>
        <actuator name="Joint_2_motor">
            <hardwareInterface>hardware_interface/EffortJointInterface</hardwareInterface>
            <mechanicalReduction>1</mechanicalReduction>
        </actuator>
    </transmission>
    <transmission name="trans_Joint_3">
        <type>transmission_interface/SimpleTransmission</type>
        <joint name="Joint_3">
            <hardwareInterface>hardware_interface/EffortJointInterface</hardwareInterface>
        </joint>
        <actuator name="Joint_3_motor">
            <hardwareInterface>hardware_interface/EffortJointInterface</hardwareInterface>
            <mechanicalReduction>1</mechanicalReduction>
        </actuator>
    </transmission>
    <transmission name="trans_Joint_4">
        <type>transmission_interface/SimpleTransmission</type>
        <joint name="Joint_4">
            <hardwareInterface>hardware_interface/EffortJointInterface</hardwareInterface>
        </joint>
        <actuator name="Joint_4_motor">
            <hardwareInterface>hardware_interface/EffortJointInterface</hardwareInterface>
            <mechanicalReduction>1</mechanicalReduction>
        </actuator>
    </transmission>
    <transmission name="trans_Joint_5">
        <type>transmission_interface/SimpleTransmission</type>
        <joint name="Joint_5">
            <hardwareInterface>hardware_interface/EffortJointInterface</hardwareInterface>
        </joint>
        <actuator name="Joint_5_motor">
            <hardwareInterface>hardware_interface/EffortJointInterface</hardwareInterface>
            <mechanicalReduction>1</mechanicalReduction>
        </actuator>
    </transmission>
    <transmission name="trans_Joint_6">
        <type>transmission_interface/SimpleTransmission</type>
        <joint name="Joint_6">
            <hardwareInterface>hardware_interface/EffortJointInterface</hardwareInterface>
        </joint>
        <actuator name="Joint_6_motor">
            <hardwareInterface>hardware_interface/EffortJointInterface</hardwareInterface>
            <mechanicalReduction>1</mechanicalReduction>
        </actuator>
    </transmission>
    <transmission name="trans_Joint_7">
        <type>transmission_interface/SimpleTransmission</type>
        <joint name="Joint_7">
            <hardwareInterface>hardware_interface/EffortJointInterface</hardwareInterface>
        </joint>
        <actuator name="Joint_7_motor">
            <hardwareInterface>hardware_interface/EffortJointInterface</hardwareInterface>
            <mechanicalReduction>1</mechanicalReduction>
        </actuator>
    </transmission>
    <gazebo>
        <plugin name="gazebo_ros_control" filename="libgazebo_ros_control.so">
            <robotNamespace>/</robotNamespace>
        </plugin>
    </gazebo>
</robot>

